<?xml version="1.0" ?>
<robot name="cafe_table">
  
  <link name="world"/>
  <link name="base_link">    
    <visual>
      <origin xyz="0.05 0 0.02" rpy="0 0 0" />
      <geometry>
        <box size="0.56 0.56 0.04" />
      </geometry>
    </visual>
    
    <inertial>
      <origin xyz="0.05 0 0.02" rpy="0 0 0" />
      <mass value="100"/>
      <inertia
        ixx="2.627" ixy="0.0" ixz="0.0"
        iyy="5.227" iyz="0.0"
        izz="2.627"/>
      <!-- <gravity>0</gravity> -->
    </inertial>
    
    <collision>
      <origin xyz="0.05 0 0.02" rpy="0 0 0" />
      <geometry>
        <box size="0.56 0.56 0.04" />
      </geometry>
    </collision>  
    
    <!-- <gazebo reference="base_link">
      <material>Gazebo/Blue</material>
      <gravity>0</gravity>
      <mu1>1000</mu1>
      <mu2>1000</mu2>
    </gazebo>  -->
  </link>
  
  <joint name="fixed" type="fixed">
    <parent link="world"/>
    <child link="base_link"/>
  </joint>
  
  <link name="column">    
    <visual>
      <origin xyz="0 0 0.37" rpy="0 0 0" />
      <geometry>
        <box size="0.08 0.08 0.74" />
      </geometry>
    </visual>
    
    <inertial>
      <origin xyz="0 0 0.37" rpy="0 0 0" />
      <mass value="10"/>
      <inertia
        ixx="0.5" ixy="0.0" ixz="0.0"
        iyy="0.01" iyz="0.0"
        izz="0.5"/>
      <!-- <gravity>0</gravity> -->
    </inertial>
    
    <collision>
      <origin xyz="0 0 0.37" rpy="0 0 0" />
      <geometry>
        <box size="0.08 0.08 0.74" />
      </geometry>
    </collision> 
    
    <!-- <gazebo reference="column">
      <material>Gazebo/Blue</material>
      <gravity>0</gravity>
      <mu1>1000</mu1>
      <mu2>1000</mu2>
    </gazebo> -->
    
  </link> 
  
  <joint name="base_to_column" type="fixed">
    <parent link="base_link"/>
    <child link="column"/>
  </joint>
  
  <link name="surface1">
    <visual>
      <origin xyz="0.23 0 0.755" rpy="0 0 0" />
      <geometry>
        <box size="0.913 2 0.04" />
      </geometry>
    </visual>
    
    <inertial>
      <origin xyz="0.23 0 0.755" rpy="0 0 0" />
      <mass value="1"/>
      <inertia
        ixx="0.07" ixy="0.0" ixz="0.0"
        iyy="0.40" iyz="0.0"
        izz="0.33"/>
      <!-- <gravity>0</gravity> -->
    </inertial>
    
    <collision>
      <origin xyz="0.23 0 0.755" rpy="0 0 0" />
      <geometry>
        <box size="0.913 2 0.04" />
      </geometry>
    </collision>
    
    <!-- <gazebo reference="surface1">
      <material>Gazebo/Blue</material>
      <gravity>0</gravity>
      <mu1>1000</mu1>
      <mu2>1000</mu2>
    </gazebo> -->
    
  </link>
  
  <joint name="column_to_surface1" type="fixed">
    <parent link="column"/>
    <child link="surface1"/>
  </joint>
  
  <link name="surface3">
    <visual>
      <origin xyz="-0.2633 0.9565 0.755" rpy="0 0 0" /> <!---0.2765-->
      <geometry>
        <box size="0.0735 0.087 0.04" />
      </geometry>
    </visual>
    
    <inertial>
      <origin xyz="-0.2633 0.9565 0.755" rpy="0 0 0" />
      <mass value="1"/>
      <inertia
        ixx="0.001" ixy="0.0" ixz="0.0"
        iyy="0.001" iyz="0.0"
        izz="0.001"/>
      <!-- <gravity>0</gravity> -->
    </inertial>
    
    <collision>
      <origin xyz="-0.2633 0.9565 0.755" rpy="0 0 0" />
      <geometry>
        <box size="0.0735 0.087 0.04" />
      </geometry>
    </collision> 
    
    <!-- <gazebo reference="surface3">
      <material>Gazebo/Blue</material>
      <gravity>0</gravity> 
      <mu1>1000</mu1>
      <mu2>1000</mu2>
    </gazebo> -->
  </link>
  
  <link name="surface4">    
    <visual>
      <origin xyz="-0.2633 -0.9565 0.755" rpy="0 0 0" />
      <geometry>
        <box size="0.0735 0.087 0.04" />
      </geometry>
    </visual> 
    
    <inertial>
      <origin xyz="-0.2633 -0.9565 0.755" rpy="0 0 0" />
      <mass value="1"/>
      <inertia
        ixx="0.001" ixy="0.0" ixz="0.0"
        iyy="0.001" iyz="0.0"
        izz="0.001"/>
      <!-- <gravity>0</gravity> -->
    </inertial>
    
    <collision>
      <origin xyz="-0.2633 -0.9565 0.755" rpy="0 0 0" />
      <geometry>
        <box size="0.0735 0.087 0.04" />
      </geometry>
    </collision> 
    
    <!-- <gazebo reference="surface4">
      <material>Gazebo/Blue</material>
      <gravity>0</gravity>
      <mu1>1000</mu1>
      <mu2>1000</mu2>
    </gazebo> -->
  </link>
  
  <joint name="surface1_to_surface3" type="fixed">
    <parent link="surface1"/>
    <child link="surface3"/>
  </joint>
  
  <joint name="surface1_to_surface4" type="fixed">
    <parent link="surface1"/>
    <child link="surface4"/>
  </joint>
  
  <link name="surface2">
    <visual>
      <origin xyz="-0.5 0 0.755" rpy="0 0 0" />
      <geometry>
        <box size="0.4 2 0.04" />
      </geometry>
    </visual>
    
    <inertial>
      <origin xyz="-0.5 0 0.755" rpy="0 0 0" />
      <mass value="5"/>
      <inertia
        ixx="0.065" ixy="0.0" ixz="0.0"
        iyy="1.735" iyz="0.0"
        izz="1.665"/>
      <!-- <contact_coefficients mu="10"/> -->
      <!-- <gravity>0</gravity> -->
    </inertial>
    
    <collision>
      <origin xyz="-0.5 0 0.755" rpy="0 0 0" />
      <geometry>
        <box size="0.4 2 0.04" />
      </geometry>
    </collision> 
    
    <!-- <gazebo reference="surface2">
      <material>Gazebo/Blue</material>
      <gravity>0</gravity>
      <mu1>1000</mu1>
      <mu2>1000</mu2>
    </gazebo> -->
    
  </link>
  
  <joint name="surface3_to_surface2" type="fixed">
    <parent link="surface3"/>
    <child link="surface2"/>
  </joint>
  
  
  
  
  
  <link name="grey_wall_link">
    <visual>
      <origin xyz="-0.26 0 1.1525" rpy="0 0 1.57" /> 
      <geometry>
        <box size="1.826 0.05 0.755" />
      </geometry>
    </visual>
    
    <inertial>
      <origin xyz="-0.26 0 1.1525" rpy="0 0 1.57" />
      <mass value="1"/>
      <inertia
        ixx="0.048" ixy="0.0" ixz="0.0"
        iyy="0.278" iyz="0.0"
        izz="0.325"/>
      <!-- <gravity>0</gravity> -->
    </inertial>
    
    <collision>
      <origin xyz="-0.26 0 1.1525" rpy="0 0 1.57" />
      <geometry>
        <box size="1.826 0.05 0.755" />
      </geometry>
    </collision> 
    
    <!-- <gazebo reference="grey_wall_link">
      <material>Gazebo/Orange</material>
      <gravity>0</gravity>
      <mu1>1000</mu1>
      <mu2>1000</mu2>
    </gazebo> -->
  </link>
    
  <joint name="joint_wall" type="prismatic">
    <parent link="surface2"/>
    <child link="grey_wall_link"/>
    <axis xyz="0 0 1"/>
    <!-- <limit effort="1000.0" lower="-0.223" upper="0" velocity="0.5" /> -->
    <limit effort="1000.0" lower="-0.755" upper="0" velocity="0.5" />
  </joint>
    

  
  <gazebo>
    <gravity>0</gravity>
  </gazebo>

  <gazebo reference="base_link">
    <material>Gazebo/Wood</material>
    <!-- <static>true</static> -->
    <gravity>0</gravity>
    <mu1>1000</mu1>
    <mu2>1000</mu2>
  </gazebo> 
  
  <gazebo reference="column">
    <material>Gazebo/Wood</material>
    <!-- <static>true</static> -->
    <!-- <gravity>0</gravity> -->
    <mu1>1000</mu1>
    <mu2>1000</mu2>
  </gazebo>
  
  <gazebo reference="surface1">
    <material>Gazebo/Wood</material>
    <!-- <static>true</static> -->
    <!-- <gravity>0</gravity> -->
    <mu1>1000</mu1>
    <mu2>1000</mu2>
  </gazebo> 
  
  <gazebo reference="surface3">
    <material>Gazebo/Wood</material>
    <!-- <static>true</static> -->
    <!-- <gravity>0</gravity> -->
    <mu1>1000</mu1>
    <mu2>1000</mu2>
  </gazebo>
  
  <gazebo reference="surface4">
    <material>Gazebo/Wood</material>
    <!-- <static>true</static> -->
    <!-- <gravity>0</gravity> -->
    <mu1>1000</mu1>
    <mu2>1000</mu2>
  </gazebo>
  
  <gazebo reference="surface2">
    <material>Gazebo/Wood</material>
    <!-- <static>true</static> -->
    <!-- <gravity>0</gravity> -->
    <mu1>1000</mu1>
    <mu2>1000</mu2>
  </gazebo>
  
  <gazebo reference="grey_wall_link">
    <material>Gazebo/Wood</material>
    <gravity>0</gravity>
    <mu1>1000</mu1>
    <mu2>1000</mu2>
  </gazebo>
  
  
  
</robot>

