<!-- <?xml version="1.0" ?>
<sdf version="1.4">
  <model name="cafe_table">
    <static>true</static>
    <link name="link">
      <collision name="surface">
        <pose>0 0 0.755 0 0 0</pose>
        <geometry>
          <box>
            <size>0.913 0.913 0.04</size>
          </box>
        </geometry>
      </collision>

      <collision name="column">
        <pose>0 0 0.37 0 0 0</pose>
        <geometry>
          <box>
            <size>0.042 0.042 0.74</size>
          </box>
        </geometry>
      </collision>

      <collision name="base">
        <pose>0 0 0.02 0 0 0</pose>
        <geometry>
          <box>
            <size>0.56 0.56 0.04</size>
          </box>
        </geometry>
      </collision>

      <visual name="visual">
        <geometry>
          <mesh>
            <uri>model://cafe_table/meshes/cafe_table.dae</uri>
          </mesh>
        </geometry>
      </visual>
    </link>
  </model>
</sdf> -->

<!-- 
<?xml version="1.0" ?>
<sdf version="1.4">
  <model name="cafe_table">
    <static>true</static>
    <link name="table_link">
     
	  <collision name="surface1">
        <pose>0.23 0 0.755 0 0 0</pose>
        <geometry>
          <box>
            <size>0.913 2 0.04</size>
          </box>
        </geometry>
      </collision>
      
      <collision name="surface2">
        <pose>-0.5 0 0.755 0 0 0</pose>
        <geometry>
		  <box>
			<size>0.4 2 0.04</size>
		  </box>
		</geometry>
      </collision>
      
      <collision name="surface3">
        <pose>-0.2633 0.9565 0.755 0 0 0</pose>
        <geometry>
          <box>
            <size>0.0735 0.087 0.04</size>
          </box>
        </geometry>
      </collision>
      
      
      <collision name="surface4">
        <pose>-0.2633 -0.9565 0.755 0 0 0</pose>
        <geometry>
          <box>
            <size>0.0735 0.087 0.04</size>
          </box>
        </geometry>
      </collision> 

      <collision name="column">
        <pose>0 0 0.37 0 0 0</pose>
        <geometry>
          <box>
            <size>0.042 0.042 0.74</size>
          </box>
        </geometry>
      </collision>

      <collision name="base">
        <pose>0.05 0 0.02 0 0 0</pose>
        <geometry>
          <box>
            <size>0.56 0.56 0.04</size>
          </box>
        </geometry>
      </collision>

      
      <visual name="visual_surface1">
        <pose>0.23 0 0.755 0 0 0</pose>
        <geometry>
          <box>
            <size>0.913 2 0.04</size>
          </box>
        </geometry>
      </visual> 
      
      <visual name="visual_surface2">
        <pose>-0.5 0 0.755 0 0 0</pose>
        <geometry>
		  <box>
			<size>0.4 2 0.04</size>
		  </box>
		</geometry>
      </visual>
      
      <visual name="visual_surface3">
        <pose>-0.2633 0.9565 0.755 0 0 0</pose>
        <geometry>
          <box>
            <size>0.0735 0.087 0.04</size>
          </box>
        </geometry>
      </visual>
      
      <visual name="visual_surface4">
        <pose>-0.2633 -0.9565 0.755 0 0 0</pose>
        <geometry>
          <box>
            <size>0.0735 0.087 0.04</size>
          </box>
        </geometry>
      </visual> 
      
      <visual name="visual_column">
        <pose>0 0 0.37 0 0 0</pose>
        <geometry>
          <box>
            <size>0.042 0.042 0.74</size>
          </box>
        </geometry>
      </visual> 
      
      <visual name="visual_base">
        <pose>0.05 0 0.02 0 0 0</pose>
        <geometry>
          <box>
            <size>0.56 0.56 0.04</size>
          </box>
        </geometry>
      </visual>
      
    </link>
    
    <link name="grey_wall_link">
      <pose>-0.26 0 1.1525 0 0 1.57</pose> 
      <collision name="collision">
        <geometry>
          <box>
            <size>1.826 0.05 0.755</size>
          </box>
        </geometry>
      </collision>
      <visual name="visual">
        <cast_shadows>false</cast_shadows>
        <geometry>
          <box>
            <size>1.826 0.05 0.755</size>
          </box>
        </geometry>
        <material>
          <script>
            <uri>model://cafe_table/materials/scripts</uri>
            <uri>model://cafe_table/materials/textures</uri>
            <name>vrc/grey_wall</name>
          </script>
        </material>
      </visual>
    </link>
    
    <joint name="wall_joint" type="prismatic">
      <parent>table_link</parent>
      <child>grey_wall_link</child>
      <axis>
        <xyz>0 0 1</xyz>
        <limit>
			<lower>-0.223</lower>
			<upper>0</upper>
		</limit>
      </axis>
    </joint>
    
  </model>
</sdf>


-->


<?xml version="1.0" ?>
<robot name="cafe_table">
  <!-- <static>true</static> -->
  <link name="table_link">
      
	<collision name="surface1">
      <origin xyz="0.23 0 0.755" rpy="0 0 0" />
      <geometry>
        <box size="0.913 2 0.04" />
      </geometry>
    </collision>
      
    <collision name="surface2">
      <origin xyz"-0.5 0 0.755" rpy="0 0 0" />
      <geometry>
		<box size="0.4 2 0.04" />
      </geometry>
    </collision>
      
    <collision name="surface3">
      <origin xyz="-0.2633 0.9565 0.755" rpy="0 0 0" />
      <geometry>
        <box size="0.0735 0.087 0.04" />
      </geometry>
    </collision>
      
      
    <collision name="surface4">
      <origin xyz="-0.2633 -0.9565 0.755" rpy="0 0 0" />
      <geometry>
        <box size="0.0735 0.087 0.04" />
      </geometry>
    </collision> 

    <collision name="column">
      <origin xyz="0 0 0.37" rpy"0 0 0" />
      <geometry>
        <box size="0.042 0.042 0.74" />
      </geometry>
    </collision>

    <collision name="base">
      <origin xyz="0.05 0 0.02" rpy="0 0 0" />
      <geometry>
        <box size="0.56 0.56 0.04" />
      </geometry>
    </collision>
      
    <visual name="visual_surface1">
      <origin xyz="0.23 0 0.755" rpy="0 0 0" />
      <geometry>
        <box size="0.913 2 0.04" />
      </geometry>
    </visual> 
      
    <visual name="visual_surface2">
      <origin xyz="-0.5 0 0.755" rpy="0 0 0" />
      <geometry>
		<box size="0.4 2 0.04" />
	  </geometry>
    </visual>
      
    <visual name="visual_surface3">
      <origin xyz="-0.2633 0.9565 0.755" rpy="0 0 0" /> <!---0.2765-->
      <geometry>
        <box size="0.0735 0.087 0.04" />
      </geometry>
    </visual>
      
    <visual name="visual_surface4">
      <origin xyz="-0.2633 -0.9565 0.755" rpy="0 0 0" />
      <geometry>
        <box size="0.0735 0.087 0.04" />
      </geometry>
    </visual> 
      
    <visual name="visual_column">
      <origin xyz="0 0 0.37" rpy="0 0 0" />
      <geometry>
        <box size="0.042 0.042 0.74" />
      </geometry>
    </visual> 
      
    <visual name="visual_base">
      <origin xyz="0.05 0 0.02" rpy="0 0 0" </pose>
      <geometry>
        <box size="0.56 0.56 0.04" />
      </geometry>
    </visual>
      
  </link>
  
  <link name="grey_wall_link">
    <collision name="collision">
      <origin xyz="-0.26 0 1.1525" rpy="0 0 1.57" /> 
      <geometry>
        <box size="1.826 0.05 0.755" />
      </geometry>
    </collision>
    <visual name="visual">
      <origin xyz="-0.26 0 1.1525" rpy="0 0 1.57" /> 
      <cast_shadows>false</cast_shadows>
      <geometry>
        <box size="1.826 0.05 0.755" />
      </geometry>
      <material>
        <script>
          <uri>model://cafe_table/materials/scripts</uri>
          <uri>model://cafe_table/materials/textures</uri>
          <name>vrc/grey_wall</name>
        </script>
      </material>
    </visual>
  </link>
    
  <joint name="wall_joint" type="prismatic">
    <parent link="table_link"/>
    <child link="grey_wall_link"/>
    <axis xyz="0 0 1"/>
    <limit effort="1000.0" lower="-0.223" upper="0" velocity="0.5" />
  </joint>
    
</robot>
